<?xml version="1.0"?>
<robot name="scout_rover">

  <link name="base_link">
    <visual>
      <geometry><box size="0.4 0.3 0.1"/></geometry>
      <material name="blue"><color rgba="0.1 0.1 0.8 1.0"/></material>
    </visual>
    <collision>
      <geometry><box size="0.4 0.3 0.1"/></geometry>
    </collision>
    <inertial>
      <mass value="5.0"/>
      <origin xyz="0 0 0" rpy="0 0 0"/>
      <inertia ixx="0.0416" ixy="0.0" ixz="0.0" iyy="0.0708" iyz="0.0" izz="0.104"/>
    </inertial>
  </link>

  <link name="right_wheel">
    <visual>
      <geometry><cylinder radius="0.1" length="0.05"/></geometry>
      <material name="black"><color rgba="0.1 0.1 0.1 1.0"/></material>
    </visual>
    <collision>
      <geometry><cylinder radius="0.1" length="0.05"/></geometry>
    </collision>
    <inertial>
      <mass value="1.0"/>
      <origin xyz="0 0 0" rpy="0 0 0"/>
      <inertia ixx="0.0027" ixy="0.0" ixz="0.0" iyy="0.0027" iyz="0.0" izz="0.005"/>
    </inertial>
  </link>

  <joint name="base_to_right_wheel" type="continuous">
    <parent link="base_link"/>
    <child link="right_wheel"/>
    <origin xyz="0.15 -0.175 0.0" rpy="1.5708 0 0"/>
    <axis xyz="0 0 1"/>
  </joint>

  <link name="left_wheel">
    <visual>
      <geometry><cylinder radius="0.1" length="0.05"/></geometry>
      <material name="black"/>
    </visual>
    <collision>
      <geometry><cylinder radius="0.1" length="0.05"/></geometry>
    </collision>
    <inertial>
      <mass value="1.0"/>
      <origin xyz="0 0 0" rpy="0 0 0"/>
      <inertia ixx="0.0027" ixy="0.0" ixz="0.0" iyy="0.0027" iyz="0.0" izz="0.005"/>
    </inertial>
  </link>

  <joint name="base_to_left_wheel" type="continuous">
    <parent link="base_link"/>
    <child link="left_wheel"/>
    <origin xyz="0.15 0.175 0.0" rpy="-1.5708 0 0"/>
    <axis xyz="0 0 1"/>
  </joint>

  <link name="caster_wheel">
    <visual>
      <geometry><sphere radius="0.05"/></geometry>
      <material name="grey"><color rgba="0.6 0.6 0.6 1.0"/></material>
    </visual>
    <collision>
      <geometry><sphere radius="0.05"/></geometry>
    </collision>
    <inertial>
      <mass value="0.5"/>
      <origin xyz="0 0 0" rpy="0 0 0"/>
      <inertia ixx="0.0005" ixy="0.0" ixz="0.0" iyy="0.0005" iyz="0.0" izz="0.0005"/>
    </inertial>
  </link>

  <joint name="base_to_caster" type="fixed">
    <parent link="base_link"/>
    <child link="caster_wheel"/>
    <origin xyz="-0.15 0.0 -0.05" rpy="0 0 0"/>
  </joint>

  <gazebo reference="caster_wheel">
    <mu1>0.001</mu1>
    <mu2>0.001</mu2>
  </gazebo>

  <link name="camera_link">
    <visual>
      <geometry><box size="0.05 0.05 0.05"/></geometry>
      <material name="red"><color rgba="0.8 0.1 0.1 1.0"/></material>
    </visual>
    <collision>
      <geometry><box size="0.05 0.05 0.05"/></geometry>
    </collision>
    <inertial>
      <mass value="0.1"/>
      <origin xyz="0 0 0" rpy="0 0 0"/>
      <inertia ixx="0.00004" ixy="0.0" ixz="0.0" iyy="0.00004" iyz="0.0" izz="0.00004"/>
    </inertial>
  </link>

  <joint name="base_to_camera" type="fixed">
    <parent link="base_link"/>
    <child link="camera_link"/>
    <origin xyz="0.2 0.0 0.05" rpy="0 0 0"/>
  </joint>

  <link name="camera_link_optical"></link>
  <joint name="camera_optical_joint" type="fixed">
    <parent link="camera_link"/>
    <child link="camera_link_optical"/>
    <origin xyz="0 0 0" rpy="-1.5708 0 -1.5708"/>
  </joint>

</robot>
